Error while getting Updates: urllib3 HTTPError ('Connection aborted.', ConnectionResetError(104, 'Connection reset by peer'))
No error handlers are registered, logging exception.
Traceback (most recent call last):
  File "/usr/local/lib/python3.6/dist-packages/telegram/vendor/ptb_urllib3/urllib3/connectionpool.py", line 617, in urlopen
    chunked=chunked)
  File "/usr/local/lib/python3.6/dist-packages/telegram/vendor/ptb_urllib3/urllib3/connectionpool.py", line 402, in _make_request
    six.raise_from(e, None)
  File "<string>", line 2, in raise_from
  File "/usr/local/lib/python3.6/dist-packages/telegram/vendor/ptb_urllib3/urllib3/connectionpool.py", line 398, in _make_request
    httplib_response = conn.getresponse()
  File "/usr/lib/python3.6/http/client.py", line 1373, in getresponse
    response.begin()
  File "/usr/lib/python3.6/http/client.py", line 311, in begin
    version, status, reason = self._read_status()
  File "/usr/lib/python3.6/http/client.py", line 272, in _read_status
    line = str(self.fp.readline(_MAXLINE + 1), "iso-8859-1")
  File "/usr/lib/python3.6/socket.py", line 586, in readinto
    return self._sock.recv_into(b)
  File "/usr/lib/python3.6/ssl.py", line 1012, in recv_into
    return self.read(nbytes, buffer)
  File "/usr/lib/python3.6/ssl.py", line 874, in read
    return self._sslobj.read(len, buffer)
  File "/usr/lib/python3.6/ssl.py", line 631, in read
    v = self._sslobj.read(len, buffer)
ConnectionResetError: [Errno 104] Connection reset by peer

During handling of the above exception, another exception occurred:

Traceback (most recent call last):
  File "/usr/local/lib/python3.6/dist-packages/telegram/utils/request.py", line 224, in _request_wrapper
    resp = self._con_pool.request(*args, **kwargs)
  File "/usr/local/lib/python3.6/dist-packages/telegram/vendor/ptb_urllib3/urllib3/request.py", line 70, in request
    **urlopen_kw)
  File "/usr/local/lib/python3.6/dist-packages/telegram/vendor/ptb_urllib3/urllib3/request.py", line 148, in request_encode_body
    return self.urlopen(method, url, **extra_kw)
  File "/usr/local/lib/python3.6/dist-packages/telegram/vendor/ptb_urllib3/urllib3/poolmanager.py", line 244, in urlopen
    response = conn.urlopen(method, u.request_uri, **kw)
  File "/usr/local/lib/python3.6/dist-packages/telegram/vendor/ptb_urllib3/urllib3/connectionpool.py", line 666, in urlopen
    _stacktrace=sys.exc_info()[2])
  File "/usr/local/lib/python3.6/dist-packages/telegram/vendor/ptb_urllib3/urllib3/util/retry.py", line 347, in increment
    raise six.reraise(type(error), error, _stacktrace)
  File "/usr/local/lib/python3.6/dist-packages/telegram/vendor/ptb_urllib3/urllib3/packages/six.py", line 685, in reraise
    raise value.with_traceback(tb)
  File "/usr/local/lib/python3.6/dist-packages/telegram/vendor/ptb_urllib3/urllib3/connectionpool.py", line 617, in urlopen
    chunked=chunked)
  File "/usr/local/lib/python3.6/dist-packages/telegram/vendor/ptb_urllib3/urllib3/connectionpool.py", line 402, in _make_request
    six.raise_from(e, None)
  File "<string>", line 2, in raise_from
  File "/usr/local/lib/python3.6/dist-packages/telegram/vendor/ptb_urllib3/urllib3/connectionpool.py", line 398, in _make_request
    httplib_response = conn.getresponse()
  File "/usr/lib/python3.6/http/client.py", line 1373, in getresponse
    response.begin()
  File "/usr/lib/python3.6/http/client.py", line 311, in begin
    version, status, reason = self._read_status()
  File "/usr/lib/python3.6/http/client.py", line 272, in _read_status
    line = str(self.fp.readline(_MAXLINE + 1), "iso-8859-1")
  File "/usr/lib/python3.6/socket.py", line 586, in readinto
    return self._sock.recv_into(b)
  File "/usr/lib/python3.6/ssl.py", line 1012, in recv_into
    return self.read(nbytes, buffer)
  File "/usr/lib/python3.6/ssl.py", line 874, in read
    return self._sslobj.read(len, buffer)
  File "/usr/lib/python3.6/ssl.py", line 631, in read
    v = self._sslobj.read(len, buffer)
telegram.vendor.ptb_urllib3.urllib3.exceptions.ProtocolError: ('Connection aborted.', ConnectionResetError(104, 'Connection reset by peer'))

During handling of the above exception, another exception occurred:

Traceback (most recent call last):
  File "/usr/local/lib/python3.6/dist-packages/telegram/ext/updater.py", line 379, in _network_loop_retry
    if not action_cb():
  File "/usr/local/lib/python3.6/dist-packages/telegram/ext/updater.py", line 340, in polling_action_cb
    allowed_updates=allowed_updates)
  File "<decorator-gen-31>", line 2, in get_updates
  File "/usr/local/lib/python3.6/dist-packages/telegram/bot.py", line 67, in decorator
    result = func(*args, **kwargs)
  File "/usr/local/lib/python3.6/dist-packages/telegram/bot.py", line 2138, in get_updates
    result = self._request.post(url, data, timeout=float(read_latency) + float(timeout))
  File "/usr/local/lib/python3.6/dist-packages/telegram/utils/request.py", line 333, in post
    **urlopen_kwargs)
  File "/usr/local/lib/python3.6/dist-packages/telegram/utils/request.py", line 230, in _request_wrapper
    raise NetworkError('urllib3 HTTPError {}'.format(error))
telegram.error.NetworkError: urllib3 HTTPError ('Connection aborted.', ConnectionResetError(104, 'Connection reset by peer'))
No error handlers are registered, logging exception.
Traceback (most recent call last):
  File "/usr/local/lib/python3.6/dist-packages/telegram/ext/dispatcher.py", line 340, in process_update
    handler.handle_update(update, self, check, context)
  File "/usr/local/lib/python3.6/dist-packages/telegram/ext/handler.py", line 119, in handle_update
    return self.callback(update, context)
  File "/root/learn_a_language/firewall.py", line 39, in wrapper
    func(*args)
  File "main.py", line 64, in callback_response
    return delete_card(update, context)
  File "/root/learn_a_language/firewall.py", line 39, in wrapper
    func(*args)
  File "main.py", line 145, in delete_card
    os.remove(config["cards_path"] + update.callback_query.data[4:])
FileNotFoundError: [Errno 2] No such file or directory: '/root/learn_a_language/Cards/weifhuweilrfhwefgyvdfsvsdfvsdfvsdfv'
No error handlers are registered, logging exception.
Traceback (most recent call last):
  File "/usr/local/lib/python3.6/dist-packages/telegram/ext/dispatcher.py", line 340, in process_update
    handler.handle_update(update, self, check, context)
  File "/usr/local/lib/python3.6/dist-packages/telegram/ext/handler.py", line 119, in handle_update
    return self.callback(update, context)
  File "/root/learn_a_language/firewall.py", line 39, in wrapper
    func(*args)
  File "main.py", line 64, in callback_response
    return delete_card(update, context)
  File "/root/learn_a_language/firewall.py", line 39, in wrapper
    func(*args)
  File "main.py", line 145, in delete_card
    os.remove(config["cards_path"] + update.callback_query.data[4:])
FileNotFoundError: [Errno 2] No such file or directory: '/root/learn_a_language/Cards/weifhuweilrfhwefgyvdfsvsdfvsdfvsdfv'
No error handlers are registered, logging exception.
Traceback (most recent call last):
  File "/usr/local/lib/python3.6/dist-packages/telegram/ext/dispatcher.py", line 340, in process_update
    handler.handle_update(update, self, check, context)
  File "/usr/local/lib/python3.6/dist-packages/telegram/ext/handler.py", line 119, in handle_update
    return self.callback(update, context)
  File "/root/learn_a_language/firewall.py", line 39, in wrapper
    func(*args)
  File "main.py", line 64, in callback_response
    return delete_card(update, context)
  File "/root/learn_a_language/firewall.py", line 39, in wrapper
    func(*args)
  File "main.py", line 145, in delete_card
    os.remove(config["cards_path"] + update.callback_query.data[4:])
FileNotFoundError: [Errno 2] No such file or directory: '/root/learn_a_language/Cards/weifhuweilrfhwefgyvdfsvsdfvsdfvsdfv'
No error handlers are registered, logging exception.
Traceback (most recent call last):
  File "/usr/local/lib/python3.6/dist-packages/telegram/ext/dispatcher.py", line 340, in process_update
    handler.handle_update(update, self, check, context)
  File "/usr/local/lib/python3.6/dist-packages/telegram/ext/handler.py", line 119, in handle_update
    return self.callback(update, context)
  File "/root/learn_a_language/firewall.py", line 39, in wrapper
    func(*args)
  File "main.py", line 64, in callback_response
    return delete_card(update, context)
  File "/root/learn_a_language/firewall.py", line 39, in wrapper
    func(*args)
  File "main.py", line 145, in delete_card
    os.remove(config["cards_path"] + update.callback_query.data[4:])
FileNotFoundError: [Errno 2] No such file or directory: '/root/learn_a_language/Cards/weifhuweilrfhwefgyvdfsvsdfvsdfvsdfv'
No error handlers are registered, logging exception.
Traceback (most recent call last):
  File "/usr/local/lib/python3.6/dist-packages/telegram/ext/dispatcher.py", line 340, in process_update
    handler.handle_update(update, self, check, context)
  File "/usr/local/lib/python3.6/dist-packages/telegram/ext/handler.py", line 119, in handle_update
    return self.callback(update, context)
  File "/root/learn_a_language/firewall.py", line 39, in wrapper
    func(*args)
  File "main.py", line 64, in callback_response
    return delete_card(update, context)
  File "/root/learn_a_language/firewall.py", line 39, in wrapper
    func(*args)
  File "main.py", line 145, in delete_card
    os.remove(config["cards_path"] + update.callback_query.data[4:])
FileNotFoundError: [Errno 2] No such file or directory: '/root/learn_a_language/Cards/weifhuweilrfhwefgyvdfsvsdfvsdfvsdfv'
No error handlers are registered, logging exception.
Traceback (most recent call last):
  File "/usr/local/lib/python3.6/dist-packages/telegram/ext/dispatcher.py", line 340, in process_update
    handler.handle_update(update, self, check, context)
  File "/usr/local/lib/python3.6/dist-packages/telegram/ext/handler.py", line 119, in handle_update
    return self.callback(update, context)
  File "/root/learn_a_language/firewall.py", line 39, in wrapper
    func(*args)
  File "main.py", line 64, in callback_response
    return delete_card(update, context)
  File "/root/learn_a_language/firewall.py", line 39, in wrapper
    func(*args)
  File "main.py", line 145, in delete_card
    os.remove(config["cards_path"] + update.callback_query.data[4:])
FileNotFoundError: [Errno 2] No such file or directory: '/root/learn_a_language/Cards/Moew 🐈'
